<?xml version="1.0"?>
<robot name="cube" xmlns:drake="https://drake.mit.edu/">
    <link name="worldfixed" />
    <link name="cube_body">
        <inertial>
            <origin xyz="0 0 0" rpy="0 0 0"/>
            <mass value="0.37" />
            <inertia
                ixx="0.00081"
                ixy="0"
                ixz="0"
                iyy="0.00081"
                iyz="0"
                izz="0.00081"/>
        </inertial>
        <visual>
            <origin xyz="0 0 0" rpy="0 0 0" />
            <geometry>
                <box size="0.1048 0.1048 0.1048"/>
            </geometry>
            <material name="pennred">
                <color rgba="0.6 0 0 1.0" />
            </material>
        </visual>
        <collision>
            <geometry>
                <box size="0.1048 0.1048 0.1048"/>
            </geometry>
            <origin xyz="0 0 0" rpy="0 0 0" />
            <drake:proximity_properties>
                <drake:mu_static value="0.15" />
                <drake:rigid_hydroelastic />
                <drake:mesh_resolution_hint value="0.001" />
                <drake:point_contact_stiffness value="10800.0" />
                <drake:hunt_crossley_dissipation value="0.4" />
            </drake:proximity_properties>
        </collision>
    </link>

    <joint name="worldfixed_to_cube_body" type="planar">
        <parent link="worldfixed"/>
        <child link="cube_body"/>
        <axis xyz="0 -1 0"/>
    </joint>
</robot>