<?xml version="1.0"?>
<robot name="elbow">
    <link name="elbow_1">
        <inertial>
            <origin xyz="0 0 0" rpy="0 0 0"/>
            <mass value="0.37"/>
            <inertia
                ixx="0.0006167"
                ixy="0"
                ixz="0"
                iyy="0.0006167"
                iyz="0"
                izz="0.0006167"/>
        </inertial>
        <visual>
            <origin xyz="0 0 0" rpy="0 0 0" />
            <geometry>
                <mesh filename="contactnets_elbow_half.obj"/>
            </geometry>
            <material name="green">
                <color rgba="0 1 0 1.0" />
            </material>
        </visual>
        <collision>
            <geometry>
                <mesh filename="contactnets_elbow_half.obj"/>
            </geometry>
            <drake:proximity_properties>
                <drake:mu_static value="0.3" />
            </drake:proximity_properties>
            <origin xyz="0 0 0" rpy="0 0 0" />
        </collision>
    </link>

    <link name="elbow_2">
        <inertial>
            <origin xyz="0.035 0 0" rpy="0 0 0"/>
            <mass value="0.37"/>
            <inertia
                ixx="0.0006167"
                ixy="0"
                ixz="0"
                iyy="0.0006167"
                iyz="0"
                izz="0.0006167"/>
        </inertial>
        <visual>
            <origin xyz="0.035 0 0" rpy="0 0 0" />
            <geometry>
                <mesh filename="contactnets_elbow_half.obj"/>
            </geometry>
            <material name="blue">
                <color rgba="0 0 1 1.0" />
            </material>
        </visual>
        <collision>
            <geometry>
                <mesh filename="contactnets_elbow_half.obj"/>
            </geometry>
            <drake:proximity_properties>
                <drake:mu_static value="0.3" />
            </drake:proximity_properties>
            <origin xyz="0.035 0 0" rpy="0 0 0" />
        </collision>
    </link>

    <joint name="hinge_1_to_2" type="continuous">
        <parent link="elbow_1"/>
        <child link="elbow_2"/>
        <origin xyz="-0.035 0.06 0" rpy="0 0 0" />
        <axis xyz="0 1 0" />
    </joint>

    <drake:collision_filter_group name="elbow_group">
        <drake:member link="elbow_1"/>
        <drake:member link="elbow_2"/>
        <drake:ignored_collision_filter_group name="elbow_group"/>
    </drake:collision_filter_group>

</robot>

