<?xml version="1.0" ?>

<robot name="spherebot" xmlns:drake="https://drake.mit.edu/">
  <!--
    Frames are defined such that they all align with the base frame when all
    joints are at position zero.

    In zero-configuration the origins of all joints are in one line.

    In zero-configuration the origin of the base link is exactly above the
    finger tip which should make it easy to place the finger in the world.
    -->
  <!-- Define the global worldfixed and place all other objects relative to it. -->
  
  <material name="finger_0_material">
    <color rgba="0.6 0.0 0.0 1.0"/>
  </material>
  <material name="finger_1_material">
    <color rgba="0.6 0.0 0.0 1.0"/>
  </material>

  <link name="worldfixed" />

  <link name="finger_0">
   <visual>
      <origin rpy="0 0 0" xyz="0 0 0"/>
      <geometry>
        <sphere radius="0.01"/>
      </geometry>
      <material name="finger_0_material"/>
    </visual>
    <inertial>
      <origin rpy="0 0 0" xyz="0 0 0"/>
      <mass value="0.01"/>
      <inertia
                ixx="0.0000086697"
                ixy="0"
                ixz="0"
                iyy="0.0000086697"
                iyz="0"
                izz="0.0000086697"/>
    </inertial>
    <collision>
      <origin rpy="0 0 0" xyz="0 0 0"/>
      <geometry>
        <sphere radius="0.01"/>
      </geometry>
        <drake:proximity_properties>
          <drake:mu_static value="1"/>
          <drake:mu_dynamic value="1"/>
          <drake:rigid_hydroelastic />
          <drake:mesh_resolution_hint value="0.001" />
          <drake:point_contact_stiffness value="10800.0" />
          <drake:hunt_crossley_dissipation value="0.4" />
        </drake:proximity_properties>

    </collision>
  </link>
  
  <link name="finger_0_fake_x" />
  
  <link name="finger_0_fake_y" />
  
  <joint name="finger_0_to_base_x" type="prismatic">
    <origin xyz="0 0 0" />
    <parent link="worldfixed"/>
    <child link="finger_0_fake_x"/>
    <axis xyz="1 0 0"/>
  </joint>
  <joint name="finger_0_to_base_y" type="fixed">
    <origin xyz="0 0 0" />
    <parent link="finger_0_fake_x"/>
    <child link="finger_0_fake_y"/>
    <axis xyz="0 1 0"/>
  </joint>
  <joint name="finger_0_to_base_z" type="prismatic">
    <origin xyz="0 0 0" />
    <parent link="finger_0_fake_y"/>
    <child link="finger_0"/>
    <axis xyz="0 0 1"/>
  </joint>
  
   <transmission name="finger_0_to_base_trans_x" type="SimpleTransmission">
    <actuator name="finger_0_to_base_act_x"/>
    <joint name="finger_0_to_base_x"/>
    <mechanicalReduction>1</mechanicalReduction>
  </transmission>
  <!--
     <transmission name="finger_0_to_base_trans_y" type="SimpleTransmission">
    <actuator name="finger_0_to_base_act_y"/>
    <joint name="finger_0_to_base_y"/>
    <mechanicalReduction>1</mechanicalReduction>
  </transmission>
-->  
     <transmission name="finger_0_to_base_trans_z" type="SimpleTransmission">
    <actuator name="finger_0_to_base_act_z"/>
    <joint name="finger_0_to_base_z"/>
    <mechanicalReduction>1</mechanicalReduction>
  </transmission>


<!-- Note: Group Name Collision happens between URDFs
  <drake:collision_filter_group name="finger_0_group">
  <drake:member link="finger_0"/>
  <drake:ignored_collision_filter_group name="finger_0_group"/>
  </drake:collision_filter_group>
-->

<!--
  <link name="finger_1">
   <visual>
      <origin rpy="0 0 0" xyz="0 0 0"/>
      <geometry>
        <sphere radius="0.01"/>
      </geometry>
      <material name="finger_1_material"/>
    </visual>
    <inertial>
      <origin rpy="0 0 0" xyz="0 0 0"/>
      <mass value="0.01"/>
      <inertia
                ixx="0.0000086697"
                ixy="0"
                ixz="0"
                iyy="0.0000086697"
                iyz="0"
                izz="0.0000086697"/>
    </inertial>
    <collision>
      <origin rpy="0 0 0" xyz="0 0 0"/>
      <geometry>
        <sphere radius="0.01"/>
      </geometry>
        <drake:proximity_properties>
          <drake:mu_static value="1"/>
          <drake:mu_dynamic value="1"/>
          <drake:rigid_hydroelastic />
          <drake:mesh_resolution_hint value="0.001" />
          <drake:point_contact_stiffness value="10800.0" />
          <drake:hunt_crossley_dissipation value="0.4" />
        </drake:proximity_properties>

    </collision>
  </link>
  
  <link name="finger_1_fake_x" />
  
  <link name="finger_1_fake_y" />
  
  <joint name="finger_1_to_base_x" type="prismatic">
    <origin xyz="0 0 0" />
    <parent link="worldfixed"/>
    <child link="finger_1_fake_x"/>
    <axis xyz="1 0 0"/>
  </joint>
  <joint name="finger_1_to_base_y" type="fixed">
    <origin xyz="0 0 0" />
    <parent link="finger_1_fake_x"/>
    <child link="finger_1_fake_y"/>
    <axis xyz="0 1 0"/>
  </joint>
  <joint name="finger_1_to_base_z" type="prismatic">
    <origin xyz="0 0 0.0524" />
    <parent link="finger_1_fake_y"/>
    <child link="finger_1"/>
    <axis xyz="0 0 1"/>
  </joint>
  
   <transmission name="finger_1_to_base_trans_x" type="SimpleTransmission">
    <actuator name="finger_1_to_base_act_x"/>
    <joint name="finger_1_to_base_x"/>
    <mechanicalReduction>1</mechanicalReduction>
  </transmission>
  
  <!--
     <transmission name="finger_1_to_base_trans_y" type="SimpleTransmission">
    <actuator name="finger_1_to_base_act_y"/>
    <joint name="finger_1_to_base_y"/>
    <mechanicalReduction>1</mechanicalReduction>
  </transmission>
  -->
  <!--
     <transmission name="finger_1_to_base_trans_z" type="SimpleTransmission">
    <actuator name="finger_1_to_base_act_z"/>
    <joint name="finger_1_to_base_z"/>
    <mechanicalReduction>1</mechanicalReduction>
  </transmission>
-->

<!-- Note: Group Name Collision happens between URDFs
  <drake:collision_filter_group name="finger_1_group">
  <drake:member link="finger_1"/>
  <drake:ignored_collision_filter_group name="finger_1_group"/>
  </drake:collision_filter_group>
-->
</robot>